E
======================================================================
ERROR: test_compile (rnvs_tb.common.CompileTest)
----------------------------------------------------------------------
Traceback (most recent call last):
  File "/usr/local/lib/python3.8/dist-packages/urllib3/response.py", line 444, in _error_catcher
    yield
  File "/usr/local/lib/python3.8/dist-packages/urllib3/response.py", line 828, in read_chunked
    self._update_chunk_length()
  File "/usr/local/lib/python3.8/dist-packages/urllib3/response.py", line 758, in _update_chunk_length
    line = self._fp.fp.readline()
  File "/usr/lib/python3.8/socket.py", line 669, in readinto
    return self._sock.recv_into(b)
socket.timeout: timed out

During handling of the above exception, another exception occurred:

Traceback (most recent call last):
  File "/usr/local/lib/python3.8/dist-packages/requests/models.py", line 816, in generate
    yield from self.raw.stream(chunk_size, decode_content=True)
  File "/usr/local/lib/python3.8/dist-packages/urllib3/response.py", line 624, in stream
    for line in self.read_chunked(amt, decode_content=decode_content):
  File "/usr/local/lib/python3.8/dist-packages/urllib3/response.py", line 857, in read_chunked
    self._original_response.close()
  File "/usr/lib/python3.8/contextlib.py", line 131, in __exit__
    self.gen.throw(type, value, traceback)
  File "/usr/local/lib/python3.8/dist-packages/urllib3/response.py", line 449, in _error_catcher
    raise ReadTimeoutError(self._pool, None, "Read timed out.")
urllib3.exceptions.ReadTimeoutError: UnixHTTPConnectionPool(host='localhost', port=None): Read timed out.

During handling of the above exception, another exception occurred:

Traceback (most recent call last):
  File "/usr/local/lib/python3.8/dist-packages/rnvs_tb/common.py", line 497, in compile_cmake
    returncode = container.wait(timeout=10)['StatusCode']
  File "/usr/local/lib/python3.8/dist-packages/docker/models/containers.py", line 513, in wait
    return self.client.api.wait(self.id, **kwargs)
  File "/usr/local/lib/python3.8/dist-packages/docker/utils/decorators.py", line 19, in wrapped
    return f(self, resource_id, *args, **kwargs)
  File "/usr/local/lib/python3.8/dist-packages/docker/api/container.py", line 1320, in wait
    res = self._post(url, timeout=timeout, params=params)
  File "/usr/local/lib/python3.8/dist-packages/docker/utils/decorators.py", line 46, in inner
    return f(self, *args, **kwargs)
  File "/usr/local/lib/python3.8/dist-packages/docker/api/client.py", line 233, in _post
    return self.post(url, **self._set_request_timeout(kwargs))
  File "/usr/local/lib/python3.8/dist-packages/requests/sessions.py", line 635, in post
    return self.request("POST", url, data=data, json=json, **kwargs)
  File "/usr/local/lib/python3.8/dist-packages/requests/sessions.py", line 587, in request
    resp = self.send(prep, **send_kwargs)
  File "/usr/local/lib/python3.8/dist-packages/requests/sessions.py", line 745, in send
    r.content
  File "/usr/local/lib/python3.8/dist-packages/requests/models.py", line 899, in content
    self._content = b"".join(self.iter_content(CONTENT_CHUNK_SIZE)) or b""
  File "/usr/local/lib/python3.8/dist-packages/requests/models.py", line 822, in generate
    raise ConnectionError(e)
requests.exceptions.ConnectionError: UnixHTTPConnectionPool(host='localhost', port=None): Read timed out.

During handling of the above exception, another exception occurred:

Traceback (most recent call last):
  File "/usr/local/lib/python3.8/dist-packages/docker/api/client.py", line 268, in _raise_for_status
    response.raise_for_status()
  File "/usr/local/lib/python3.8/dist-packages/requests/models.py", line 1021, in raise_for_status
    raise HTTPError(http_error_msg, response=self)
requests.exceptions.HTTPError: 409 Client Error: Conflict for url: http+docker://localhost/v1.41/containers/9fcf011dab962fcb1916b9874fb116eeb1b300ff107ae07ffb3c02671d41d63a?v=False&link=False&force=False

The above exception was the direct cause of the following exception:

Traceback (most recent call last):
  File "/usr/local/lib/python3.8/dist-packages/rnvs_tb/common.py", line 563, in test_compile
    result = compile(self.submission, self.path, compile_log)
  File "/usr/local/lib/python3.8/dist-packages/rnvs_tb/common.py", line 521, in compile
    return compile_cmake(submission, path, log_path)
  File "/usr/local/lib/python3.8/dist-packages/rnvs_tb/common.py", line 503, in compile_cmake
    container.remove()
  File "/usr/local/lib/python3.8/dist-packages/docker/models/containers.py", line 352, in remove
    return self.client.api.remove_container(self.id, **kwargs)
  File "/usr/local/lib/python3.8/dist-packages/docker/utils/decorators.py", line 19, in wrapped
    return f(self, resource_id, *args, **kwargs)
  File "/usr/local/lib/python3.8/dist-packages/docker/api/container.py", line 1027, in remove_container
    self._raise_for_status(res)
  File "/usr/local/lib/python3.8/dist-packages/docker/api/client.py", line 270, in _raise_for_status
    raise create_api_error_from_http_exception(e) from e
  File "/usr/local/lib/python3.8/dist-packages/docker/errors.py", line 39, in create_api_error_from_http_exception
    raise cls(e, response=response, explanation=explanation) from e
docker.errors.APIError: 409 Client Error for http+docker://localhost/v1.41/containers/9fcf011dab962fcb1916b9874fb116eeb1b300ff107ae07ffb3c02671d41d63a?v=False&link=False&force=False: Conflict ("You cannot remove a running container 9fcf011dab962fcb1916b9874fb116eeb1b300ff107ae07ffb3c02671d41d63a. Stop the container before attempting removal or force remove")

----------------------------------------------------------------------
Ran 1 test in 10.866s

FAILED (errors=1)
